[2025-01-08T21:51:32.013+0000] {taskinstance.py:1083} INFO - Dependencies all met for <TaskInstance: PolygonAPI_to_BigQuery.dbt_transformation.stocks.stocks_run manual__2025-01-08T21:44:42.897309+00:00 [queued]>
[2025-01-08T21:51:32.026+0000] {taskinstance.py:1083} INFO - Dependencies all met for <TaskInstance: PolygonAPI_to_BigQuery.dbt_transformation.stocks.stocks_run manual__2025-01-08T21:44:42.897309+00:00 [queued]>
[2025-01-08T21:51:32.027+0000] {taskinstance.py:1279} INFO - 
--------------------------------------------------------------------------------
[2025-01-08T21:51:32.027+0000] {taskinstance.py:1280} INFO - Starting attempt 2 of 2
[2025-01-08T21:51:32.028+0000] {taskinstance.py:1281} INFO - 
--------------------------------------------------------------------------------
[2025-01-08T21:51:32.044+0000] {taskinstance.py:1300} INFO - Executing <Task(DbtRunLocalOperator): dbt_transformation.stocks.stocks_run> on 2025-01-08 21:44:42.897309+00:00
[2025-01-08T21:51:32.050+0000] {standard_task_runner.py:55} INFO - Started process 6711 to run task
[2025-01-08T21:51:32.053+0000] {standard_task_runner.py:82} INFO - Running: ['***', 'tasks', 'run', 'PolygonAPI_to_BigQuery', 'dbt_transformation.stocks.stocks_run', 'manual__2025-01-08T21:44:42.897309+00:00', '--job-id', '593', '--raw', '--subdir', 'DAGS_FOLDER/polygon_to_bigquery.py', '--cfg-path', '/tmp/tmpgfmhkr_9']
[2025-01-08T21:51:32.054+0000] {standard_task_runner.py:83} INFO - Job 593: Subtask dbt_transformation.stocks.stocks_run
[2025-01-08T21:51:32.124+0000] {task_command.py:388} INFO - Running <TaskInstance: PolygonAPI_to_BigQuery.dbt_transformation.stocks.stocks_run manual__2025-01-08T21:44:42.897309+00:00 [running]> on host a92a1c4ce849
[2025-01-08T21:51:32.213+0000] {taskinstance.py:1509} INFO - Exporting the following env vars:
AIRFLOW_CTX_DAG_OWNER=***
AIRFLOW_CTX_DAG_ID=PolygonAPI_to_BigQuery
AIRFLOW_CTX_TASK_ID=dbt_transformation.stocks.stocks_run
AIRFLOW_CTX_EXECUTION_DATE=2025-01-08T21:44:42.897309+00:00
AIRFLOW_CTX_TRY_NUMBER=2
AIRFLOW_CTX_DAG_RUN_ID=manual__2025-01-08T21:44:42.897309+00:00
[2025-01-08T21:51:32.215+0000] {log.py:232} WARNING - [[34m2025-01-08 21:51:32,215[0m] {[34mlocal.py:[0m146} INFO[0m - [33m(astronomer-cosmos)[0m - Cloning project to writable temp directory /tmp/tmpt2iy83my from /opt/***/dbt/dbt_stock_project[0m
[2025-01-08T21:51:32.891+0000] {log.py:232} WARNING - [[34m2025-01-08 21:51:32,891[0m] {[34mconfig.py:[0m139} INFO[0m - [33m(astronomer-cosmos)[0m - Using user-supplied profiles.yml at /opt/***/dbt/profiles/profiles.yml[0m
[2025-01-08T21:51:32.892+0000] {log.py:232} WARNING - [[34m2025-01-08 21:51:32,892[0m] {[34mlocal.py:[0m176} INFO[0m - [33m(astronomer-cosmos)[0m - Trying to run the command:
 ['/home/***/.local/bin/dbt', 'run', '--models', 'stocks', '--profiles-dir', '/opt/***/dbt/profiles', '--profile', 'default', '--target', 'dev']
From /tmp/tmpt2iy83my/dbt_project[0m
[2025-01-08T21:51:32.894+0000] {log.py:232} WARNING - [[34m2025-01-08 21:51:32,892[0m] {[34mlocal.py:[0m177} INFO[0m - [33m(astronomer-cosmos)[0m - Using environment variables keys: dict_keys(['AIRFLOW_CTX_DAG_OWNER', 'AIRFLOW_CTX_DAG_ID', 'AIRFLOW_CTX_TASK_ID', 'AIRFLOW_CTX_EXECUTION_DATE', 'AIRFLOW_CTX_TRY_NUMBER', 'AIRFLOW_CTX_DAG_RUN_ID'])[0m
[2025-01-08T21:51:32.894+0000] {log.py:232} WARNING - [[34m2025-01-08 21:51:32,894[0m] {[34msubprocess.py:[0m60} INFO[0m - [33m(astronomer-cosmos)[0m - Tmp dir root location: 
 /tmp[0m
[2025-01-08T21:51:32.895+0000] {log.py:232} WARNING - [[34m2025-01-08 21:51:32,894[0m] {[34msubprocess.py:[0m73} INFO[0m - [33m(astronomer-cosmos)[0m - Running command: ['/home/***/.local/bin/dbt', 'run', '--models', 'stocks', '--profiles-dir', '/opt/***/dbt/profiles', '--profile', 'default', '--target', 'dev'][0m
[2025-01-08T21:51:32.907+0000] {log.py:232} WARNING - [[34m2025-01-08 21:51:32,906[0m] {[34msubprocess.py:[0m84} INFO[0m - [33m(astronomer-cosmos)[0m - Command output:[0m
[2025-01-08T21:51:36.257+0000] {log.py:232} WARNING - [[34m2025-01-08 21:51:36,257[0m] {[34msubprocess.py:[0m94} INFO[0m - [33m(astronomer-cosmos)[0m - [0m21:51:36  Running with dbt=1.5.11[0m
[2025-01-08T21:51:36.273+0000] {log.py:232} WARNING - [[34m2025-01-08 21:51:36,273[0m] {[34msubprocess.py:[0m94} INFO[0m - [33m(astronomer-cosmos)[0m - [0m21:51:36  Error importing adapter: No module named 'dbt.adapters.bigquery'[0m
[2025-01-08T21:51:36.274+0000] {log.py:232} WARNING - [[34m2025-01-08 21:51:36,274[0m] {[34msubprocess.py:[0m94} INFO[0m - [33m(astronomer-cosmos)[0m - [0m21:51:36  Encountered an error:[0m
[2025-01-08T21:51:36.275+0000] {log.py:232} WARNING - [[34m2025-01-08 21:51:36,274[0m] {[34msubprocess.py:[0m94} INFO[0m - [33m(astronomer-cosmos)[0m - Runtime Error[0m
[2025-01-08T21:51:36.275+0000] {log.py:232} WARNING - [[34m2025-01-08 21:51:36,275[0m] {[34msubprocess.py:[0m94} INFO[0m - [33m(astronomer-cosmos)[0m -   Credentials in profile "default", target "dev" invalid: Runtime Error[0m
[2025-01-08T21:51:36.276+0000] {log.py:232} WARNING - [[34m2025-01-08 21:51:36,276[0m] {[34msubprocess.py:[0m94} INFO[0m - [33m(astronomer-cosmos)[0m -     Could not find adapter type bigquery![0m
[2025-01-08T21:51:37.234+0000] {log.py:232} WARNING - [[34m2025-01-08 21:51:37,234[0m] {[34msubprocess.py:[0m98} INFO[0m - [33m(astronomer-cosmos)[0m - Command exited with return code 2[0m
[2025-01-08T21:51:37.255+0000] {taskinstance.py:1768} ERROR - Task failed with exception
Traceback (most recent call last):
  File "/home/airflow/.local/lib/python3.7/site-packages/cosmos/operators/local.py", line 282, in execute
    result = self.build_and_run_cmd(context=context)
  File "/home/airflow/.local/lib/python3.7/site-packages/cosmos/operators/local.py", line 194, in build_and_run_cmd
    return self.run_command(cmd=dbt_cmd, env=env, context=context)
  File "/home/airflow/.local/lib/python3.7/site-packages/cosmos/operators/local.py", line 185, in run_command
    self.exception_handling(result)
  File "/home/airflow/.local/lib/python3.7/site-packages/cosmos/operators/local.py", line 79, in exception_handling
    *result.full_output,
airflow.exceptions.AirflowException: ('dbt command failed. The command returned a non-zero exit code 2. Details: ', '\x1b[0m21:51:36  Running with dbt=1.5.11', "\x1b[0m21:51:36  Error importing adapter: No module named 'dbt.adapters.bigquery'", '\x1b[0m21:51:36  Encountered an error:', 'Runtime Error', '  Credentials in profile "default", target "dev" invalid: Runtime Error', '    Could not find adapter type bigquery!')
[2025-01-08T21:51:37.260+0000] {taskinstance.py:1323} INFO - Marking task as FAILED. dag_id=PolygonAPI_to_BigQuery, task_id=dbt_transformation.stocks.stocks_run, execution_date=20250108T214442, start_date=20250108T215132, end_date=20250108T215137
[2025-01-08T21:51:37.278+0000] {standard_task_runner.py:105} ERROR - Failed to execute job 593 for task dbt_transformation.stocks.stocks_run (('dbt command failed. The command returned a non-zero exit code 2. Details: ', '\x1b[0m21:51:36  Running with dbt=1.5.11', "\x1b[0m21:51:36  Error importing adapter: No module named 'dbt.adapters.bigquery'", '\x1b[0m21:51:36  Encountered an error:', 'Runtime Error', '  Credentials in profile "default", target "dev" invalid: Runtime Error', '    Could not find adapter type bigquery!'); 6711)
[2025-01-08T21:51:37.287+0000] {local_task_job.py:208} INFO - Task exited with return code 1
[2025-01-08T21:51:37.325+0000] {taskinstance.py:2578} INFO - 0 downstream tasks scheduled from follow-on schedule check
