[2025-01-18T13:40:36.224+0000] {taskinstance.py:1149} INFO - Dependencies not met for <TaskInstance: PolygonAPI_to_BigQuery.sync_data_connection_3 scheduled__2025-01-17T00:00:00+00:00 [failed]>, dependency 'Task Instance State' FAILED: Task is in the 'failed' state.
[2025-01-18T13:40:36.251+0000] {local_task_job_runner.py:154} INFO - Task is not able to be run
