[2024-12-05T05:48:46.680+0000] {taskinstance.py:1083} INFO - Dependencies all met for <TaskInstance: PolygonAPI_to_BigQuery.sync_polygon_data scheduled__2024-12-05T04:00:00+00:00 [queued]>
[2024-12-05T05:48:46.698+0000] {taskinstance.py:1083} INFO - Dependencies all met for <TaskInstance: PolygonAPI_to_BigQuery.sync_polygon_data scheduled__2024-12-05T04:00:00+00:00 [queued]>
[2024-12-05T05:48:46.699+0000] {taskinstance.py:1279} INFO - 
--------------------------------------------------------------------------------
[2024-12-05T05:48:46.699+0000] {taskinstance.py:1280} INFO - Starting attempt 1 of 2
[2024-12-05T05:48:46.700+0000] {taskinstance.py:1281} INFO - 
--------------------------------------------------------------------------------
[2024-12-05T05:48:46.727+0000] {taskinstance.py:1300} INFO - Executing <Task(AirbyteTriggerSyncOperator): sync_polygon_data> on 2024-12-05 04:00:00+00:00
[2024-12-05T05:48:46.733+0000] {standard_task_runner.py:55} INFO - Started process 38174 to run task
[2024-12-05T05:48:46.738+0000] {standard_task_runner.py:82} INFO - Running: ['***', 'tasks', 'run', 'PolygonAPI_to_BigQuery', 'sync_polygon_data', 'scheduled__2024-12-05T04:00:00+00:00', '--job-id', '67', '--raw', '--subdir', 'DAGS_FOLDER/polygon_to_BigQuery_sync.py', '--cfg-path', '/tmp/tmpf2tle4nb']
[2024-12-05T05:48:46.739+0000] {standard_task_runner.py:83} INFO - Job 67: Subtask sync_polygon_data
[2024-12-05T05:48:46.860+0000] {task_command.py:388} INFO - Running <TaskInstance: PolygonAPI_to_BigQuery.sync_polygon_data scheduled__2024-12-05T04:00:00+00:00 [running]> on host 1b9e534b4855
[2024-12-05T05:48:47.014+0000] {taskinstance.py:1509} INFO - Exporting the following env vars:
AIRFLOW_CTX_DAG_OWNER=***
AIRFLOW_CTX_DAG_ID=PolygonAPI_to_BigQuery
AIRFLOW_CTX_TASK_ID=sync_polygon_data
AIRFLOW_CTX_EXECUTION_DATE=2024-12-05T04:00:00+00:00
AIRFLOW_CTX_TRY_NUMBER=1
AIRFLOW_CTX_DAG_RUN_ID=scheduled__2024-12-05T04:00:00+00:00
[2024-12-05T05:48:47.039+0000] {base.py:73} INFO - Using connection ID 'airbyte_to_bigquery' for task execution.
[2024-12-05T05:48:48.123+0000] {airbyte.py:77} INFO - Job 39 was submitted to Airbyte Server
[2024-12-05T05:48:48.125+0000] {airbyte.py:79} INFO - Waiting for job 39 to complete
[2024-12-05T05:49:05.928+0000] {base.py:73} INFO - Using connection ID 'airbyte_to_bigquery' for task execution.
[2024-12-05T13:42:00.284+0000] {base.py:73} INFO - Using connection ID 'airbyte_to_bigquery' for task execution.
[2024-12-05T13:42:07.457+0000] {base.py:73} INFO - Using connection ID 'airbyte_to_bigquery' for task execution.
[2024-12-05T13:42:10.518+0000] {base.py:73} INFO - Using connection ID 'airbyte_to_bigquery' for task execution.
[2024-12-05T13:42:10.612+0000] {local_task_job.py:273} WARNING - State of this instance has been externally set to up_for_retry. Terminating instance.
[2024-12-05T13:42:10.614+0000] {process_utils.py:133} INFO - Sending Signals.SIGTERM to group 38174. PIDs of all processes in the group: [38174]
[2024-12-05T13:42:10.614+0000] {process_utils.py:84} INFO - Sending the signal Signals.SIGTERM to group 38174
[2024-12-05T13:42:10.615+0000] {taskinstance.py:1479} ERROR - Received SIGTERM. Terminating subprocesses.
[2024-12-05T13:42:10.615+0000] {airbyte.py:88} INFO - on_kill: cancel the airbyte Job 39
[2024-12-05T13:42:10.624+0000] {base.py:73} INFO - Using connection ID 'airbyte_to_bigquery' for task execution.
[2024-12-05T13:42:12.082+0000] {taskinstance.py:1768} ERROR - Task failed with exception
Traceback (most recent call last):
  File "/home/airflow/.local/lib/python3.7/site-packages/airflow/providers/airbyte/operators/airbyte.py", line 80, in execute
    self.hook.wait_for_job(job_id=self.job_id, wait_seconds=self.wait_seconds, timeout=self.timeout)
  File "/home/airflow/.local/lib/python3.7/site-packages/airflow/providers/airbyte/hooks/airbyte.py", line 67, in wait_for_job
    time.sleep(wait_seconds)
  File "/home/airflow/.local/lib/python3.7/site-packages/airflow/models/taskinstance.py", line 1481, in signal_handler
    raise AirflowException("Task received SIGTERM signal")
airflow.exceptions.AirflowException: Task received SIGTERM signal
[2024-12-05T13:42:12.097+0000] {taskinstance.py:1323} INFO - Marking task as FAILED. dag_id=PolygonAPI_to_BigQuery, task_id=sync_polygon_data, execution_date=20241205T040000, start_date=20241205T054846, end_date=20241205T134212
[2024-12-05T13:42:12.136+0000] {standard_task_runner.py:105} ERROR - Failed to execute job 67 for task sync_polygon_data (Task received SIGTERM signal; 38174)
[2024-12-05T13:42:12.168+0000] {process_utils.py:79} INFO - Process psutil.Process(pid=38174, status='terminated', exitcode=1, started='05:48:46') (38174) terminated with exit code 1
