[2025-01-18T00:11:45.585+0000] {taskinstance.py:1159} INFO - Dependencies all met for dep_context=non-requeueable deps ti=<TaskInstance: PolygonAPI_to_BigQuery.sync_data_connection_4 scheduled__2025-01-17T00:00:00+00:00 [queued]>
[2025-01-18T00:11:45.722+0000] {taskinstance.py:1159} INFO - Dependencies all met for dep_context=requeueable deps ti=<TaskInstance: PolygonAPI_to_BigQuery.sync_data_connection_4 scheduled__2025-01-17T00:00:00+00:00 [queued]>
[2025-01-18T00:11:45.723+0000] {taskinstance.py:1361} INFO - Starting attempt 1 of 2
[2025-01-18T00:11:45.803+0000] {taskinstance.py:1382} INFO - Executing <Task(AirbyteTriggerSyncOperator): sync_data_connection_4> on 2025-01-17 00:00:00+00:00
[2025-01-18T00:11:45.815+0000] {standard_task_runner.py:57} INFO - Started process 179 to run task
[2025-01-18T00:11:45.828+0000] {standard_task_runner.py:84} INFO - Running: ['***', 'tasks', 'run', 'PolygonAPI_to_BigQuery', 'sync_data_connection_4', 'scheduled__2025-01-17T00:00:00+00:00', '--job-id', '414', '--raw', '--subdir', 'DAGS_FOLDER/polygon_to_bigquery.py', '--cfg-path', '/tmp/tmp_jg9l5sm']
[2025-01-18T00:11:45.844+0000] {standard_task_runner.py:85} INFO - Job 414: Subtask sync_data_connection_4
[2025-01-18T00:11:46.025+0000] {task_command.py:415} INFO - Running <TaskInstance: PolygonAPI_to_BigQuery.sync_data_connection_4 scheduled__2025-01-17T00:00:00+00:00 [running]> on host a7a323ab681c
[2025-01-18T00:11:47.560+0000] {taskinstance.py:1660} INFO - Exporting env vars: AIRFLOW_CTX_DAG_OWNER='***' AIRFLOW_CTX_DAG_ID='PolygonAPI_to_BigQuery' AIRFLOW_CTX_TASK_ID='sync_data_connection_4' AIRFLOW_CTX_EXECUTION_DATE='2025-01-17T00:00:00+00:00' AIRFLOW_CTX_TRY_NUMBER='1' AIRFLOW_CTX_DAG_RUN_ID='scheduled__2025-01-17T00:00:00+00:00'
[2025-01-18T00:11:47.600+0000] {base.py:73} INFO - Using connection ID 'airbyte_to_bigquery' for task execution.
[2025-01-18T00:11:49.149+0000] {http.py:178} ERROR - HTTP error: Conflict
[2025-01-18T00:11:49.150+0000] {http.py:179} ERROR - {"message":"A sync is already running for: 6f9ceb50-d7d8-4978-a2d7-43ba9b472b08","exceptionClassName":"io.airbyte.commons.server.errors.ValueConflictKnownException","exceptionStack":["io.airbyte.commons.server.errors.ValueConflictKnownException: A sync is already running for: 6f9ceb50-d7d8-4978-a2d7-43ba9b472b08","\tat io.airbyte.commons.server.handlers.SchedulerHandler.readJobFromResult(SchedulerHandler.java:694)","\tat io.airbyte.commons.server.handlers.SchedulerHandler.submitManualSyncToWorker(SchedulerHandler.java:664)","\tat io.airbyte.commons.server.handlers.SchedulerHandler.syncConnection(SchedulerHandler.java:516)","\tat io.airbyte.server.apis.ConnectionApiController.lambda$syncConnection$8(ConnectionApiController.java:133)","\tat io.airbyte.server.apis.ApiHelper.execute(ApiHelper.java:26)","\tat io.airbyte.server.apis.ConnectionApiController.syncConnection(ConnectionApiController.java:133)","\tat io.airbyte.server.apis.$ConnectionApiController$Definition$Exec.dispatch(Unknown Source)","\tat io.micronaut.context.AbstractExecutableMethodsDefinition$DispatchedExecutableMethod.invoke(AbstractExecutableMethodsDefinition.java:371)","\tat io.micronaut.context.DefaultBeanContext$4.invoke(DefaultBeanContext.java:594)","\tat io.micronaut.web.router.AbstractRouteMatch.execute(AbstractRouteMatch.java:303)","\tat io.micronaut.web.router.RouteMatch.execute(RouteMatch.java:111)","\tat io.micronaut.http.context.ServerRequestContext.with(ServerRequestContext.java:103)","\tat io.micronaut.http.server.RouteExecutor.lambda$executeRoute$14(RouteExecutor.java:659)","\tat reactor.core.publisher.FluxDeferContextual.subscribe(FluxDeferContextual.java:49)","\tat reactor.core.publisher.InternalFluxOperator.subscribe(InternalFluxOperator.java:62)","\tat reactor.core.publisher.FluxSubscribeOn$SubscribeOnSubscriber.run(FluxSubscribeOn.java:194)","\tat io.micronaut.reactive.reactor.instrument.ReactorInstrumentation.lambda$init$0(ReactorInstrumentation.java:62)","\tat reactor.core.scheduler.WorkerTask.call(WorkerTask.java:84)","\tat reactor.core.scheduler.WorkerTask.call(WorkerTask.java:37)","\tat io.micronaut.scheduling.instrument.InvocationInstrumenterWrappedCallable.call(InvocationInstrumenterWrappedCallable.java:53)","\tat java.base/java.util.concurrent.FutureTask.run(FutureTask.java:317)","\tat java.base/java.util.concurrent.ThreadPoolExecutor.runWorker(ThreadPoolExecutor.java:1144)","\tat java.base/java.util.concurrent.ThreadPoolExecutor$Worker.run(ThreadPoolExecutor.java:642)","\tat java.base/java.lang.Thread.run(Thread.java:1589)"]}
[2025-01-18T00:11:49.173+0000] {taskinstance.py:1943} ERROR - Task failed with exception
Traceback (most recent call last):
  File "/home/airflow/.local/lib/python3.8/site-packages/airflow/providers/http/hooks/http.py", line 176, in check_response
    response.raise_for_status()
  File "/home/airflow/.local/lib/python3.8/site-packages/requests/models.py", line 1021, in raise_for_status
    raise HTTPError(http_error_msg, response=self)
requests.exceptions.HTTPError: 409 Client Error: Conflict for url: http://host.docker.internal:8000/api/v1/connections/sync

During handling of the above exception, another exception occurred:

Traceback (most recent call last):
  File "/home/airflow/.local/lib/python3.8/site-packages/airflow/providers/airbyte/operators/airbyte.py", line 86, in execute
    job_object = hook.submit_sync_connection(connection_id=self.connection_id)
  File "/home/airflow/.local/lib/python3.8/site-packages/airflow/providers/airbyte/hooks/airbyte.py", line 185, in submit_sync_connection
    return self.run(
  File "/home/airflow/.local/lib/python3.8/site-packages/airflow/providers/http/hooks/http.py", line 166, in run
    return self.run_and_check(session, prepped_request, extra_options)
  File "/home/airflow/.local/lib/python3.8/site-packages/airflow/providers/http/hooks/http.py", line 217, in run_and_check
    self.check_response(response)
  File "/home/airflow/.local/lib/python3.8/site-packages/airflow/providers/http/hooks/http.py", line 180, in check_response
    raise AirflowException(str(response.status_code) + ":" + response.reason)
airflow.exceptions.AirflowException: 409:Conflict
[2025-01-18T00:11:49.254+0000] {taskinstance.py:1400} INFO - Marking task as UP_FOR_RETRY. dag_id=PolygonAPI_to_BigQuery, task_id=sync_data_connection_4, execution_date=20250117T000000, start_date=20250118T001145, end_date=20250118T001149
[2025-01-18T00:11:49.312+0000] {standard_task_runner.py:104} ERROR - Failed to execute job 414 for task sync_data_connection_4 (409:Conflict; 179)
[2025-01-18T00:11:49.365+0000] {local_task_job_runner.py:228} INFO - Task exited with return code 1
[2025-01-18T00:11:49.885+0000] {taskinstance.py:2784} INFO - 0 downstream tasks scheduled from follow-on schedule check
